Workbook

Sheet Inputs
B2: Run 2 — cashflow + rebalancing manual verification
B3: run_id: run_20260802_033353_9ce1844c | generated: 2026-08-02T03:33:53Z
B5: Portfolio parameters
B6: Initial capital | C6: 100000
B7: Target weight K-SET50 | C7: 0.6
B8: Target weight M-S50 | C8: 0.4
B9: Risk-free rate (annual) | C9: 0.02
B10: Periods per year (m) | C10: 12
B11: Monthly contribution | C11: 2000
B12: Transaction cost (bps) | C12: 5
B13: Slippage (bps) | C13: 5
B14: Cost rate (txn + slippage, decimal) | C14: =(Inputs!$C$12+Inputs!$C$13)/10000 -> 0.001
B16: Raw month-end NAV per unit (source: docs/verification/4.3-raw-nav-inputs.csv)
B17: Date | C17: 2023-01-31 | D17: 2023-02-28 | E17: 2023-03-31 | F17: 2023-04-30 | G17: 2023-05-31
B18: NAV K-SET50 | C18: 34.63 | D18: 33.8033 | E18: 34.2342 | F18: 32.6194 | G18: 32.7233
B19: NAV M-S50 | C19: 23.2908 | D19: 22.7281 | E19: 23.0008 | F19: 21.9503 | G19: 21.4319

Sheet Simulation
B2: Monthly portfolio simulation ledger (independent Excel formulas)
B3: Replicates backend/app/engine/backtest.py's per-period loop exactly, one column per period.
B5: Date | C5: =Inputs!C$17 -> 2023-01-31 | D5: =Inputs!D$17 -> 2023-02-28 | E5: =Inputs!E$17 -> 2023-03-31 | F5: =Inputs!F$17 -> 2023-04-30 | G5: =Inputs!G$17 -> 2023-05-31
B6: NAV K-SET50 | C6: =Inputs!C$18 -> 34.63 | D6: =Inputs!D$18 -> 33.8033 | E6: =Inputs!E$18 -> 34.2342 | F6: =Inputs!F$18 -> 32.6194 | G6: =Inputs!G$18 -> 32.7233
B7: NAV M-S50 | C7: =Inputs!C$19 -> 23.2908 | D7: =Inputs!D$19 -> 22.7281 | E7: =Inputs!E$19 -> 23.0008 | F7: =Inputs!F$19 -> 21.9503 | G7: =Inputs!G$19 -> 21.4319
B8: Return K-SET50 (r_t) | D8: =D6/C6-1 -> -0.023872365 | E8: =E6/D6-1 -> 0.012747276 | F8: =F6/E6-1 -> -0.047169205 | G8: =G6/F6-1 -> 0.0031852211
B9: Return M-S50 (r_t) | D9: =D7/C7-1 -> -0.024159754 | E9: =E7/D7-1 -> 0.011998363 | F9: =F7/E7-1 -> -0.045672324 | G9: =G7/F7-1 -> -0.023616989
B10: Starting portfolio value | D10: =C24 -> 100000 | E10: =D24 -> 99601.261 | F10: =E24 -> 102841.05 | G10: =F24 -> 100051.66
B11: K-SET50 value after return | C11: =Inputs!$C$6*Inputs!$C$7 -> 60000 | D11: =C22*(1+D8) -> 58567.658 | E11: =D22*(1+E8) -> 60522.543 | F11: =E22*(1+F8) -> 58794.072 | G11: =F22*(1+G8) -> 60222.208
B12: M-S50 value after return | C12: =Inputs!$C$6*Inputs!$C$8 -> 40000 | D12: =C23*(1+D9) -> 39033.61 | E12: =D23*(1+E9) -> 40318.525 | F12: =E23*(1+F9) -> 39257.624 | G12: =F23*(1+G9) -> 39075.496
B13: Cashflow applied (end of period) | C13: 0 | D13: =Inputs!$C$11 -> 2000 | E13: =Inputs!$C$11 -> 2000 | F13: =Inputs!$C$11 -> 2000 | G13: =Inputs!$C$11 -> 2000
B14: K-SET50 value after cashflow | C14: =C11+Inputs!$C$7*C13 -> 60000 | D14: =D11+Inputs!$C$7*D13 -> 59767.658 | E14: =E11+Inputs!$C$7*E13 -> 61722.543 | F14: =F11+Inputs!$C$7*F13 -> 59994.072 | G14: =G11+Inputs!$C$7*G13 -> 61422.208
B15: M-S50 value after cashflow | C15: =C12+Inputs!$C$8*C13 -> 40000 | D15: =D12+Inputs!$C$8*D13 -> 39833.61 | E15: =E12+Inputs!$C$8*E13 -> 41118.525 | F15: =F12+Inputs!$C$8*F13 -> 40057.624 | G15: =G12+Inputs!$C$8*G13 -> 39875.496
B16: Total value before rebalance | C16: =C14+C15 -> 100000 | D16: =D14+D15 -> 99601.268 | E16: =E14+E15 -> 102841.07 | F16: =F14+F15 -> 100051.7 | G16: =G14+G15 -> 101297.7
B17: Target K-SET50 value (60%) | C17: =C16*Inputs!$C$7 -> 60000 | D17: =D16*Inputs!$C$7 -> 59760.761 | E17: =E16*Inputs!$C$7 -> 61704.641 | F17: =F16*Inputs!$C$7 -> 60031.018 | G17: =G16*Inputs!$C$7 -> 60778.622
B18: Target M-S50 value (40%) | C18: =C16*Inputs!$C$8 -> 40000 | D18: =D16*Inputs!$C$8 -> 39840.507 | E18: =E16*Inputs!$C$8 -> 41136.428 | F18: =F16*Inputs!$C$8 -> 40020.679 | G18: =G16*Inputs!$C$8 -> 40519.082
B19: Money turnover = sum|target-current|/2 | C19: =(ABS(C17-C14)+ABS(C18-C15))/2 -> 0 | D19: =(ABS(D17-D14)+ABS(D18-D15))/2 -> 6.8973375 | E19: =(ABS(E17-E14)+ABS(E18-E15))/2 -> 17.90224 | F19: =(ABS(F17-F14)+ABS(F18-F15))/2 -> 36.945786 | G19: =(ABS(G17-G14)+ABS(G18-G15))/2 -> 643.58535
B20: Turnover ratio = turnover/total | C20: =C19/C16 -> 0 | D20: =D19/D16 -> 6.9249495e-05 | E20: =E19/E16 -> 0.00017407676 | F20: =F19/F16 -> 0.00036926696 | G20: =G19/G16 -> 0.0063534051
B21: Rebalance cost = turnover * cost_rate | C21: =C19*Inputs!$C$14 -> 0 | D21: =D19*Inputs!$C$14 -> 0.0068973375 | E21: =E19*Inputs!$C$14 -> 0.01790224 | F21: =F19*Inputs!$C$14 -> 0.036945786 | G21: =G19*Inputs!$C$14 -> 0.64358535
B22: K-SET50 value after cost | C22: =C17-(C17/C16)*C21 -> 60000 | D22: =D17-(D17/D16)*D21 -> 59760.757 | E22: =E17-(E17/E16)*E21 -> 61704.631 | F22: =F17-(F17/F16)*F21 -> 60030.996 | G22: =G17-(G17/G16)*G21 -> 60778.236
B23: M-S50 value after cost | C23: =C18-(C18/C16)*C21 -> 40000 | D23: =D18-(D18/D16)*D21 -> 39840.504 | E23: =E18-(E18/E16)*E21 -> 41136.42 | F23: =F18-(F18/F16)*F21 -> 40020.664 | G23: =G18-(G18/G16)*G21 -> 40518.824
B24: Ending portfolio value | C24: =C22+C23 -> 100000 | D24: =D22+D23 -> 99601.261 | E24: =E22+E23 -> 102841.05 | F24: =F22+F23 -> 100051.66 | G24: =G22+G23 -> 101297.06
B25: Period performance (cashflow-neutral) | D25: =(D24-D13)/D10-1 -> -0.02398739 | E25: =(E24-E13)/E10-1 -> 0.012447531 | F25: =(F24-F13)/F10-1 -> -0.046570812 | G25: =(G24-G13)/G10-1 -> -0.0075420956

Sheet Metrics
B2: Metrics — independent Excel formulas (see docs/formula-reference.md for the cited definitions)
B4: Return & risk
B5: n (period count) | C5: =COUNT(Simulation!D25:G25) -> 4
B6: TWRR = Π(1+r_t) − 1 | C6: =EXP(SUMPRODUCT(LN(1+Simulation!D25:G25)))-1 -> -0.064963654
B7: TWRR CAGR = (1+TWRR)^(m/n) − 1 | C7: =(1+Metrics!$C$6)^(Inputs!$C$10/Metrics!$C$5)-1 -> -0.1825043
B8: Volatility = STDEV.S(r_t)·√m | C8: =STDEV(Simulation!D25:G25)*SQRT(Inputs!$C$10) -> 0.08668306
B9: Sharpe = (CAGR−Rf)/Vol | C9: =(Metrics!$C$7-Inputs!$C$9)/Metrics!$C$8 -> -2.3361462
B10: Downside deviation = √(mean(min(r_t,0)²))·√m | C10: =SQRT(SUMPRODUCT(((Simulation!D25:G25<0)*Simulation!D25:G25)^2)/Metrics!$C$5)*SQRT(Inputs!$C$10) -> 0.09166982
B11: Sortino = (CAGR−Rf)/DownsideDev | C11: =(Metrics!$C$7-Inputs!$C$9)/Metrics!$C$10 -> -2.2090618
B12: VaR 95% = max(0, −PERCENTILE.INC(r_t,0.05)) | C12: =MAX(0,-PERCENTILE(Simulation!D25:G25,0.05)) -> 0.043183299
B13: VaR 99% = max(0, −PERCENTILE.INC(r_t,0.01)) | C13: =MAX(0,-PERCENTILE(Simulation!D25:G25,0.01)) -> 0.045893309
B14: Max drawdown = min(V_t/runningPeak_t − 1) | C14: =MIN((Simulation!$C$24/MAX(Simulation!$C$24)-1),(Simulation!$D$24/MAX(Simulation!$C$24:$D$24)-1),(Simulation!$E$24/MAX(Simulation!$C$24:$E$24)-1),(Simulation!$F$24/MAX(Simulation!$C$24:$F$24)-1),(Simulation!$G$24/MAX(Simulation!$C$24:$G$24)-1)) -> -0.027123325
B15: Calmar = CAGR / |MDD| | C15: =IFERROR(Metrics!$C$7/ABS(Metrics!$C$14),"n/a") -> -6.7286845
B16: Money-weighted return (IRR)
B17: Investor cashflow (monthly-spaced, for IRR()) | C17: =-Inputs!$C$6 -> -100000 | D17: =-Simulation!D13 -> -2000 | E17: =-Simulation!E13 -> -2000 | F17: =-Simulation!F13 -> -2000 | G17: =-Simulation!G13+Simulation!G24 -> 99297.06
B18: Monthly IRR = IRR(cashflow array) | C18: =IRR(Metrics!$C$17:$G$17) -> -0.016675105
B19: Annual IRR = (1+monthlyIRR)^m − 1 | C19: =(1+Metrics!$C$18)^Inputs!$C$10-1 -> -0.18273216
B20: Benchmark-relative (benchmark = K-SET50)
B21: Benchmark CAGR = Π(1+R_b,t)^(m/n) − 1 | C21: =(EXP(SUMPRODUCT(LN(1+Simulation!D8:G8))))^(Inputs!$C$10/Metrics!$C$5)-1 -> -0.15624996
B22: Beta = COVARIANCE.S(port,bench)/VAR.S(bench) | C22: =(SUMPRODUCT((Simulation!D25:G25-AVERAGE(Simulation!D25:G25))*(Simulation!D8:G8-AVERAGE(Simulation!D8:G8)))/(COUNT(Simulation!D25:G25)-1))/VAR(Simulation!D8:G8) -> 0.90547416
B23: Alpha = CAGR − [Rf + Beta·(BenchCAGR−Rf)] | C23: =Metrics!$C$7-(Inputs!$C$9+Metrics!$C$22*(Metrics!$C$21-Inputs!$C$9)) -> -0.042914515
B24: Tracking error = STDEV.S(port−bench)·√m | C24: =SQRT(SUMPRODUCT((Simulation!D25:G25-Simulation!D8:G8-(AVERAGE(Simulation!D25:G25)-AVERAGE(Simulation!D8:G8)))^2)/(COUNT(Simulation!D25:G25)-1))*SQRT(Inputs!$C$10) -> 0.018734365
B25: Information ratio = (CAGR−BenchCAGR)/TE | C25: =(Metrics!$C$7-Metrics!$C$21)/Metrics!$C$24 -> -1.4014
B26: Correlation (portfolio, benchmark) | C26: =CORREL(Simulation!D25:G25,Simulation!D8:G8) -> 0.98172986
B27: Benchmark excess return = TWRR_port − TWRR_bench | C27: =Metrics!$C$6-(EXP(SUMPRODUCT(LN(1+Simulation!D8:G8)))-1) -> -0.0099044567
B28: Asset-level and diversification
B29: K-SET50 CAGR | C29: =(EXP(SUMPRODUCT(LN(1+Simulation!D8:G8))))^(Inputs!$C$10/Metrics!$C$5)-1 -> -0.15624996
B30: K-SET50 volatility | C30: =STDEV(Simulation!D8:G8)*SQRT(Inputs!$C$10) -> 0.093983188
B31: M-S50 CAGR | C31: =(EXP(SUMPRODUCT(LN(1+Simulation!D9:G9))))^(Inputs!$C$10/Metrics!$C$5)-1 -> -0.22083613
B32: M-S50 volatility | C32: =STDEV(Simulation!D9:G9)*SQRT(Inputs!$C$10) -> 0.082772544
B33: Correlation (K-SET50, M-S50) — Pearson, pairwise | C33: =CORREL(Simulation!D8:G8,Simulation!D9:G9) -> 0.86724837
B34: Cashflow and cost accounting
B35: Total contributed = capital + Σ(cashflow) | C35: =Inputs!$C$6+SUM(Simulation!D13:G13) -> 108000
B36: Total withdrawn | C36: =0 -> 0
B37: Total costs = Σ(rebalance cost) | C37: =SUM(Simulation!D21:G21) -> 0.70533071

Sheet Comparison
B2: Comparison — Excel (independent) vs App (real API response), 6 decimal places
B3: App output pulled verbatim from docs/verification/4.3b-result.json (run run_20260802_033353_9ce1844c).
B5: Metric | C5: Excel value | D5: App value | E5: Diff (rounded 6dp) | F5: Match?
B6: TWRR | C6: =Metrics!$C$6 -> -0.064963654 | D6: -0.064963654 | E6: =ROUND(C6-D6,6) -> 0 | F6: =IF(E6=0,"MATCH","MISMATCH") -> MATCH
B7: TWRR CAGR | C7: =Metrics!$C$7 -> -0.1825043 | D7: -0.1825043 | E7: =ROUND(C7-D7,6) -> 0 | F7: =IF(E7=0,"MATCH","MISMATCH") -> MATCH
B8: Volatility | C8: =Metrics!$C$8 -> 0.08668306 | D8: 0.08668306 | E8: =ROUND(C8-D8,6) -> 0 | F8: =IF(E8=0,"MATCH","MISMATCH") -> MATCH
B9: Sharpe ratio | C9: =Metrics!$C$9 -> -2.3361462 | D9: -2.3361462 | E9: =ROUND(C9-D9,6) -> 0 | F9: =IF(E9=0,"MATCH","MISMATCH") -> MATCH
B10: Sortino ratio | C10: =Metrics!$C$11 -> -2.2090618 | D10: -2.2090618 | E10: =ROUND(C10-D10,6) -> 0 | F10: =IF(E10=0,"MATCH","MISMATCH") -> MATCH
B11: Calmar ratio | C11: =Metrics!$C$15 -> -6.7286845 | D11: -6.7286845 | E11: =ROUND(C11-D11,6) -> 0 | F11: =IF(E11=0,"MATCH","MISMATCH") -> MATCH
B12: Value at Risk 95% | C12: =Metrics!$C$12 -> 0.043183299 | D12: 0.043183299 | E12: =ROUND(C12-D12,6) -> 0 | F12: =IF(E12=0,"MATCH","MISMATCH") -> MATCH
B13: Value at Risk 99% | C13: =Metrics!$C$13 -> 0.045893309 | D13: 0.045893309 | E13: =ROUND(C13-D13,6) -> 0 | F13: =IF(E13=0,"MATCH","MISMATCH") -> MATCH
B14: Maximum drawdown | C14: =Metrics!$C$14 -> -0.027123325 | D14: -0.027123325 | E14: =ROUND(C14-D14,6) -> 0 | F14: =IF(E14=0,"MATCH","MISMATCH") -> MATCH
B15: IRR (money-weighted) | C15: =Metrics!$C$19 -> -0.18273216 | D15: -0.18273216 | E15: =ROUND(C15-D15,6) -> 0 | F15: =IF(E15=0,"MATCH","MISMATCH") -> MATCH
B16: Benchmark excess return | C16: =Metrics!$C$27 -> -0.0099044567 | D16: -0.0099044567 | E16: =ROUND(C16-D16,6) -> 0 | F16: =IF(E16=0,"MATCH","MISMATCH") -> MATCH
B17: Beta | C17: =Metrics!$C$22 -> 0.90547416 | D17: 0.90547416 | E17: =ROUND(C17-D17,6) -> 0 | F17: =IF(E17=0,"MATCH","MISMATCH") -> MATCH
B18: Alpha | C18: =Metrics!$C$23 -> -0.042914515 | D18: -0.042914515 | E18: =ROUND(C18-D18,6) -> 0 | F18: =IF(E18=0,"MATCH","MISMATCH") -> MATCH
B19: Tracking error | C19: =Metrics!$C$24 -> 0.018734365 | D19: 0.018734365 | E19: =ROUND(C19-D19,6) -> 0 | F19: =IF(E19=0,"MATCH","MISMATCH") -> MATCH
B20: Information ratio | C20: =Metrics!$C$25 -> -1.4014 | D20: -1.4014 | E20: =ROUND(C20-D20,6) -> 0 | F20: =IF(E20=0,"MATCH","MISMATCH") -> MATCH
B21: Correlation (portfolio, benchmark) | C21: =Metrics!$C$26 -> 0.98172986 | D21: 0.98172986 | E21: =ROUND(C21-D21,6) -> 0 | F21: =IF(E21=0,"MATCH","MISMATCH") -> MATCH
B22: Correlation (K-SET50, M-S50) | C22: =Metrics!$C$33 -> 0.86724837 | D22: 0.86724837 | E22: =ROUND(C22-D22,6) -> 0 | F22: =IF(E22=0,"MATCH","MISMATCH") -> MATCH
B23: K-SET50 CAGR | C23: =Metrics!$C$29 -> -0.15624996 | D23: -0.15624996 | E23: =ROUND(C23-D23,6) -> 0 | F23: =IF(E23=0,"MATCH","MISMATCH") -> MATCH
B24: K-SET50 volatility | C24: =Metrics!$C$30 -> 0.093983188 | D24: 0.093983188 | E24: =ROUND(C24-D24,6) -> 0 | F24: =IF(E24=0,"MATCH","MISMATCH") -> MATCH
B25: M-S50 CAGR | C25: =Metrics!$C$31 -> -0.22083613 | D25: -0.22083613 | E25: =ROUND(C25-D25,6) -> 0 | F25: =IF(E25=0,"MATCH","MISMATCH") -> MATCH
B26: M-S50 volatility | C26: =Metrics!$C$32 -> 0.082772544 | D26: 0.082772544 | E26: =ROUND(C26-D26,6) -> 0 | F26: =IF(E26=0,"MATCH","MISMATCH") -> MATCH
B27: Total contributed | C27: =Metrics!$C$35 -> 108000 | D27: 108000 | E27: =ROUND(C27-D27,6) -> 0 | F27: =IF(E27=0,"MATCH","MISMATCH") -> MATCH
B28: Total withdrawn | C28: =Metrics!$C$36 -> 0 | D28: 0 | E28: =ROUND(C28-D28,6) -> 0 | F28: =IF(E28=0,"MATCH","MISMATCH") -> MATCH
B29: Total costs | C29: =Metrics!$C$37 -> 0.70533071 | D29: 0.70533071 | E29: =ROUND(C29-D29,6) -> 0 | F29: =IF(E29=0,"MATCH","MISMATCH") -> MATCH
B31: Equity curve (per-period ending value)
B32: 2023-01-31 | C32: =Simulation!C24 -> 100000 | D32: 100000 | E32: =ROUND(C32-D32,6) -> 0 | F32: =IF(E32=0,"MATCH","MISMATCH") -> MATCH
B33: 2023-02-28 | C33: =Simulation!D24 -> 99601.261 | D33: 99601.261 | E33: =ROUND(C33-D33,6) -> 0 | F33: =IF(E33=0,"MATCH","MISMATCH") -> MATCH
B34: 2023-03-31 | C34: =Simulation!E24 -> 102841.05 | D34: 102841.05 | E34: =ROUND(C34-D34,6) -> 0 | F34: =IF(E34=0,"MATCH","MISMATCH") -> MATCH
B35: 2023-04-30 | C35: =Simulation!F24 -> 100051.66 | D35: 100051.66 | E35: =ROUND(C35-D35,6) -> 0 | F35: =IF(E35=0,"MATCH","MISMATCH") -> MATCH
B36: 2023-05-31 | C36: =Simulation!G24 -> 101297.06 | D36: 101297.06 | E36: =ROUND(C36-D36,6) -> 0 | F36: =IF(E36=0,"MATCH","MISMATCH") -> MATCH
B38: Rebalance turnover & cost (per event)
B39: 2023-02-28 turnover ratio | C39: =Simulation!D20 -> 6.9249495e-05 | D39: 6.9249495e-05 | E39: =ROUND(C39-D39,6) -> 0 | F39: =IF(E39=0,"MATCH","MISMATCH") -> MATCH
B40: 2023-02-28 cost | C40: =Simulation!D21 -> 0.0068973375 | D40: 0.0068973375 | E40: =ROUND(C40-D40,6) -> 0 | F40: =IF(E40=0,"MATCH","MISMATCH") -> MATCH
B41: 2023-03-31 turnover ratio | C41: =Simulation!E20 -> 0.00017407676 | D41: 0.00017407676 | E41: =ROUND(C41-D41,6) -> 0 | F41: =IF(E41=0,"MATCH","MISMATCH") -> MATCH
B42: 2023-03-31 cost | C42: =Simulation!E21 -> 0.01790224 | D42: 0.01790224 | E42: =ROUND(C42-D42,6) -> 0 | F42: =IF(E42=0,"MATCH","MISMATCH") -> MATCH
B43: 2023-04-30 turnover ratio | C43: =Simulation!F20 -> 0.00036926696 | D43: 0.00036926696 | E43: =ROUND(C43-D43,6) -> 0 | F43: =IF(E43=0,"MATCH","MISMATCH") -> MATCH
B44: 2023-04-30 cost | C44: =Simulation!F21 -> 0.036945786 | D44: 0.036945786 | E44: =ROUND(C44-D44,6) -> 0 | F44: =IF(E44=0,"MATCH","MISMATCH") -> MATCH
...

Sheet Checks
B2: Checks
B4: Matches | C4: =COUNTIF(Comparison!F6:F46,"MATCH") -> 37
B5: Mismatches | C5: =COUNTIF(Comparison!F6:F46,"MISMATCH") -> 0
B6: Total comparisons | C6: =C4+C5 -> 37
B7: All match? | C7: =IF(C5=0,"TRUE","FALSE") -> TRUE
