Workbook

Sheet NAV
A1: nav_date | B1: M0155_2547 (M-S50) NAV | C1: M0209_2548 (K-SET50) NAV | E1: Raw data, verbatim from nav.csv (Task 1). No formulas on this sheet. Every other sheet's numbers are live formulas rooted here. Blank cells early in the series are unaligned raw SEC data (expected, and outside the 2024-02..2024-05 test window).
A2: 2015-01-05 | B2: 23.8239 | C2: 28.381
A3: 2015-01-06 | B3: 23.6462 | C3: 28.1817
A4: 2015-01-07 | B4: 24.0011 | C4: 28.6708
A5: 2015-01-08 | B5: 24.3954 | C5: 29.1099
A6: 2015-01-09 | B6: 24.38 | C6: 29.1701
A7: 2015-01-12 | B7: 24.2695 | C7: 29.1393
A8: 2015-01-13 | B8: 24.3093 | C8: 29.1234
A9: 2015-01-14 | B9: 24.076 | C9: 28.8328
A10: 2015-01-15 | B10: 24.052 | C10: 28.8158
A11: 2015-01-16 | B11: 23.989 | C11: 28.6944
A12: 2015-01-19 | B12: 24.2942 | C12: 29.0979
A13: 2015-01-20 | B13: 24.2592 | C13: 29.069
... A96: 2015-05-27 | B96: 23.5227 | C96: 28.7717
A97: 2015-05-28 | B97: 23.3496
A98: 2015-05-29 | B98: 23.3363 | C98: 28.598
A99: 2015-06-02 | B99: 23.022 | C99: 28.2145
A100: 2015-06-03 | B100: 23.0984 | C100: 28.3223
A101: 2015-06-04 | B101: 23.2552 | C101: 28.4914
A102: 2015-06-05 | B102: 23.5613 | C102: 28.8507
A103: 2015-06-08 | B103: 23.5581 | C103: 28.8234
A104: 2015-06-09 | B104: 23.2646 | C104: 28.4712
A105: 2015-06-10 | B105: 23.4925 | C105: 28.7624
A106: 2015-06-11 | B106: 23.635 | C106: 28.984
A107: 2015-06-12 | B107: 23.4953 | C107: 28.7879
A108: 2015-06-15 | B108: 23.4172 | C108: 28.6334
A109: 2015-06-16 | B109: 23.4133 | C109: 28.6593
... A486: 2016-12-28 | B486: 22.9408 | C486: 28.7845
A487: 2016-12-29 | B487: 23.1832
A488: 2016-12-30 | B488: 23.2609
A489: 2017-01-04 | B489: 23.6133 | C489: 29.6635
A490: 2017-01-05 | B490: 23.7212 | C490: 29.8011
A491: 2017-01-06 | B491: 23.6659 | C491: 29.7519
A492: 2017-01-09 | B492: 23.5492 | C492: 29.5898
A493: 2017-01-10 | B493: 23.668 | C493: 29.7443
A494: 2017-01-11 | B494: 23.6209 | C494: 29.6887
A495: 2017-01-12 | B495: 23.5702 | C495: 29.6096
A496: 2017-01-13 | B496: 23.6601 | C496: 29.7277
A497: 2017-01-16 | B497: 23.5687
A498: 2017-01-17 | B498: 23.5124
...

Sheet Returns
A1: nav_date | B1: M0155_2547 return | C1: M0209_2548 return | F1: TEST WINDOW — request.timePeriod 2024-02-29..2024-05-31, dataFrequency=monthly
B2: =IFERROR(NAV!B3/NAV!B2-1,"") | C2: =IFERROR(NAV!C3/NAV!C2-1,"") | F2: Month-end anchors pulled out of NAV by INDEX/MATCH (live). 2024-03-29 is March's anchor: 2024-03-30/31 were non-trading days. 4 anchors -> 3 monthly returns (the brief said 4; the real calendar yields 3, matching result.json's 3-element monthlyReturnsPct).
A3: =NAV!A4 | B3: =IFERROR(NAV!B4/NAV!B3-1,"") | C3: =IFERROR(NAV!C4/NAV!C3-1,"") | F3: month_end | G3: NAV M0155_2547 | H3: NAV M0209_2548 | I3: ret M0155_2547 | J3: ret M0209_2548
A4: =NAV!A5 | B4: =IFERROR(NAV!B5/NAV!B4-1,"") | C4: =IFERROR(NAV!C5/NAV!C4-1,"") | F4: 2024-02-29 | G4: =INDEX(NAV!B:B,MATCH($F4,NAV!$A:$A,0)) | H4: =INDEX(NAV!C:C,MATCH($F4,NAV!$A:$A,0))
A5: =NAV!A6 | B5: =IFERROR(NAV!B6/NAV!B5-1,"") | C5: =IFERROR(NAV!C6/NAV!C5-1,"") | F5: 2024-03-29 | G5: =INDEX(NAV!B:B,MATCH($F5,NAV!$A:$A,0)) | H5: =INDEX(NAV!C:C,MATCH($F5,NAV!$A:$A,0)) | I5: =G5/G4-1 | J5: =H5/H4-1
A6: =NAV!A7 | B6: =IFERROR(NAV!B7/NAV!B6-1,"") | C6: =IFERROR(NAV!C7/NAV!C6-1,"") | F6: 2024-04-30 | G6: =INDEX(NAV!B:B,MATCH($F6,NAV!$A:$A,0)) | H6: =INDEX(NAV!C:C,MATCH($F6,NAV!$A:$A,0)) | I6: =G6/G5-1 | J6: =H6/H5-1
A7: =NAV!A8 | B7: =IFERROR(NAV!B8/NAV!B7-1,"") | C7: =IFERROR(NAV!C8/NAV!C7-1,"") | F7: 2024-05-31 | G7: =INDEX(NAV!B:B,MATCH($F7,NAV!$A:$A,0)) | H7: =INDEX(NAV!C:C,MATCH($F7,NAV!$A:$A,0)) | I7: =G7/G6-1 | J7: =H7/H6-1
A8: =NAV!A9 | B8: =IFERROR(NAV!B9/NAV!B8-1,"") | C8: =IFERROR(NAV!C9/NAV!C8-1,"")
A9: =NAV!A10 | B9: =IFERROR(NAV!B10/NAV!B9-1,"") | C9: =IFERROR(NAV!C10/NAV!C9-1,"") | F9: Test-window return count (live) | G9: =COUNT(Returns!$J$5:$J$7)
A10: =NAV!A11 | B10: =IFERROR(NAV!B11/NAV!B10-1,"") | C10: =IFERROR(NAV!C11/NAV!C10-1,"") | F10: Periods per year (m) | G10: 12
A11: =NAV!A12 | B11: =IFERROR(NAV!B12/NAV!B11-1,"") | C11: =IFERROR(NAV!C12/NAV!C11-1,"") | F11: Risk-free rate % p.a. (request.constraints.riskFreeRatePct) | G11: 1.5
A12: =NAV!A13 | B12: =IFERROR(NAV!B13/NAV!B12-1,"") | C12: =IFERROR(NAV!C13/NAV!C12-1,"")
A13: =NAV!A14 | B13: =IFERROR(NAV!B14/NAV!B13-1,"") | C13: =IFERROR(NAV!C14/NAV!C13-1,"")
A14: =NAV!A15 | B14: =IFERROR(NAV!B15/NAV!B14-1,"") | C14: =IFERROR(NAV!C15/NAV!C14-1,"")
A15: =NAV!A16 | B15: =IFERROR(NAV!B16/NAV!B15-1,"") | C15: =IFERROR(NAV!C16/NAV!C15-1,"")
A16: =NAV!A17 | B16: =IFERROR(NAV!B17/NAV!B16-1,"") | C16: =IFERROR(NAV!C17/NAV!C16-1,"")
A17: =NAV!A18 | B17: =IFERROR(NAV!B18/NAV!B17-1,"") | C17: =IFERROR(NAV!C18/NAV!C17-1,"")
A18: =NAV!A19 | B18: =IFERROR(NAV!B19/NAV!B18-1,"") | C18: =IFERROR(NAV!C19/NAV!C18-1,"")
A19: =NAV!A20 | B19: =IFERROR(NAV!B20/NAV!B19-1,"") | C19: =IFERROR(NAV!C20/NAV!C19-1,"")
A20: =NAV!A21 | B20: =IFERROR(NAV!B21/NAV!B20-1,"") | C20: =IFERROR(NAV!C21/NAV!C20-1,"")
A21: =NAV!A22 | B21: =IFERROR(NAV!B22/NAV!B21-1,"") | C21: =IFERROR(NAV!C22/NAV!C21-1,"")
A22: =NAV!A23 | B22: =IFERROR(NAV!B23/NAV!B22-1,"") | C22: =IFERROR(NAV!C23/NAV!C22-1,"")
A23: =NAV!A24 | B23: =IFERROR(NAV!B24/NAV!B23-1,"") | C23: =IFERROR(NAV!C24/NAV!C23-1,"")
... A2716: =NAV!A2717 | B2716: =IFERROR(NAV!B2717/NAV!B2716-1,"") | C2716: =IFERROR(NAV!C2717/NAV!C2716-1,"")

Sheet Weights
A1: WEIGHTS TAB VERIFICATION
A2: Yellow cells are GIVEN (pasted from result.json) and are what the live formulas are checked against. Everything else is a formula chain rooted in NAV.
A4: projId | B4: displayName | C4: given weight (result.json) | D4: mean monthly return (live) | E4: annualized return % (live) | F4: given assetSummary.expectedReturnPct | G4: diff | H4: annualized vol % (live) | I4: given assetSummary.volatilityPct | J4: diff
A5: M0209_2548 | B5: K-SET50 | C5: 0.97491886 | D5: =AVERAGE(Returns!$J$5:$J$7) | E5: =D5*Returns!$G$10*100 | F5: -0.35 | G5: =ROUND(E5,2)-F5 | H5: =STDEV(Returns!$J$5:$J$7)*SQRT(Returns!$G$10)*100 | I5: 4.21 | J5: =ROUND(H5,2)-I5
A6: M0155_2547 | B6: M-S50 | C6: 0.02508114 | D6: =AVERAGE(Returns!$I$5:$I$7) | E6: =D6*Returns!$G$10*100 | F6: -11.92 | G6: =ROUND(E6,2)-F6 | H6: =STDEV(Returns!$I$5:$I$7)*SQRT(Returns!$G$10)*100 | I6: 9.64 | J6: =ROUND(H6,2)-I6
B7: sum of weights (must be 1) | C7: =SUM(C5:C6)
A9: Portfolio expected return
A10: monthly (SUMPRODUCT of weights x mean returns) | C10: =SUMPRODUCT(C5:C6,D5:D6)
A11: annualized % | C11: =C10*Returns!$G$10*100 | D11: given optimalPoint.expectedReturnPct | E11: -0.64 | F11: =ROUND(C11,2)-E11
A13: Covariance matrix Sigma (monthly, sample / ddof=1)
B14: M0209_2548 | C14: M0155_2547
A15: M0209_2548 | B15: =VAR(Returns!$J$5:$J$7) | C15: =SUMPRODUCT((Returns!$J$5:$J$7-AVERAGE(Returns!$J$5:$J$7))*(Returns!$I$5:$I$7-AVERAGE(Returns!$I$5:$I$7)))/(3-1)
A16: M0155_2547 | B16: =SUMPRODUCT((Returns!$J$5:$J$7-AVERAGE(Returns!$J$5:$J$7))*(Returns!$I$5:$I$7-AVERAGE(Returns!$I$5:$I$7)))/(3-1) | C16: =VAR(Returns!$I$5:$I$7)
A18: correlation (live) | C18: =$C$15/SQRT($B$15*$C$16) | D18: given correlations[0].correlation | E18: 0.95 | F18: =ROUND(C18,2)-E18
A20: Portfolio variance (monthly) = w1^2*s11 + w2^2*s22 + 2*w1*w2*s12 | C20: =C5^2*$B$15+C6^2*$C$16+2*C5*C6*$C$15
A21: Portfolio volatility (monthly) = SQRT(variance) | C21: =SQRT(C20)
A22: Portfolio volatility ANNUALIZED % = monthly*SQRT(12)*100 | C22: =SQRT(C20)*SQRT(Returns!$G$10)*100 | D22: given selectedRiskMeasure.optimizedValue | E22: 4.33 | F22: =ROUND(C22,2)-E22 | G22: =IF(ABS(F22)<0.005,"OK","MISMATCH")
A24: Risk contribution %
A25: projId | B25: computed % (live) | C25: given riskContributionPct | D25: diff | E25: check (tolerance 0.005 = given is rounded to 2dp)
A26: M0209_2548 | B26: =C5*($B$15*C5+$C$15*C6)/C20*100 | C26: 94.67 | D26: =ROUND(B26,2)-C26 | E26: =IF(ABS(D26)<0.005,"OK","MISMATCH")
A27: M0155_2547 | B27: =C6*($C$15*C5+$C$16*C6)/C20*100 | C27: 5.33 | D27: =ROUND(B27,2)-C27 | E27: =IF(ABS(D27)<0.005,"OK","MISMATCH")
A29: Tolerance is 0.005 rather than the brief's 1e-6 because result.json's reported values are rounded to 2 decimal places by the API layer; the computed side is rounded to 2dp before differencing, so an exact match shows as 0.

Sheet Frontier
A1: FRONTIER TAB VERIFICATION
A2: Each frontier point's own weights are GIVEN; its volatility, expected return and Sharpe are recomputed live from the same Sigma/mu built on the Weights sheet (which is itself rooted in NAV).
A4: point # | B4: w M0209_2548 (given) | C4: w M0155_2547 (given) | D4: volatility % (live) | E4: given volatilityPct | F4: diff | G4: expected return % (live) | H4: given expectedReturnPct | I4: diff | J4: sharpe (live) | K4: given sharpe | L4: diff | M4: check
A5: 1 | B5: 1 | C5: 0 | D5: =SQRT(B5^2*Weights!$B$15+C5^2*Weights!$C$16+2*B5*C5*Weights!$C$15)*SQRT(Returns!$G$10)*100 | E5: 4.21 | F5: =ROUND(D5,2)-E5 | G5: =(B5*Weights!$D$5+C5*Weights!$D$6)*Returns!$G$10*100 | H5: -0.35 | I5: =ROUND(G5,2)-H5 | J5: =(G5-Returns!$G$11)/D5 | K5: -0.44 | L5: =ROUND(J5,2)-K5 | M5: =IF(AND(ABS(F5)<0.005,ABS(I5)<0.005,ABS(L5)<0.005),"OK","MISMATCH")
A7: result.json's frontier holds a single point (100% M0209_2548) because maxHoldings=2 over a 2-fund universe with a 3-observation window collapses the efficient set. Sharpe uses the annualized excess return over riskFreeRatePct=1.5.

Sheet Performance
A1: PERFORMANCE TAB VERIFICATION
A2: Formulas below are taken verbatim from docs/formula-reference.md: annualized_return R_ann = PRODUCT(1+r_t)^(m/n)-1; annualized_volatility sigma_ann = std(r_t, ddof=1)*SQRT(m); sortino_ratio sigma_down = SQRT(mean(min(r_t,0)^2))*SQRT(m), Sortino = (R_ann - R_f)/sigma_down with MAR=0; max_drawdown MDD = min(V_t/Peak_t - 1).
A4: month_end | B4: portfolio return (live) | C4: given monthlyReturnsPct | D4: diff | E4: growth of 1 (V_t) | F4: running peak | G4: drawdown | H4: downside min(r,0)
A5: start (2024-02-29) | E5: 1 | F5: =MAX($E$5:E5) | G5: =E5/F5-1
A6: =Returns!F5 | B6: =Returns!J5*Weights!$C$5+Returns!I5*Weights!$C$6 | C6: 1.2 | D6: =ROUND(B6*100,2)-C6 | E6: =E5*(1+B6) | F6: =MAX($E$5:E6) | G6: =E6/F6-1 | H6: =MIN(B6,0)
A7: =Returns!F6 | B7: =Returns!J6*Weights!$C$5+Returns!I6*Weights!$C$6 | C7: -0.06 | D7: =ROUND(B7*100,2)-C7 | E7: =E6*(1+B7) | F7: =MAX($E$5:E7) | G7: =E7/F7-1 | H7: =MIN(B7,0)
A8: =Returns!F7 | B8: =Returns!J7*Weights!$C$5+Returns!I7*Weights!$C$6 | C8: -1.3 | D8: =ROUND(B8*100,2)-C8 | E8: =E7*(1+B8) | F8: =MAX($E$5:E8) | G8: =E8/F8-1 | H8: =MIN(B8,0)
A10: Metrics
A11: metric | B11: formula-reference.md name | C11: computed (live) | D11: given performanceSummary[0] | E11: diff | F11: check
A12: CAGR % | B12: annualized_return | C12: =($E$8^(Returns!$G$10/3)-1)*100 | D12: -0.7 | E12: =ROUND(C12,2)-D12 | F12: =IF(ABS(E12)<0.005,"OK","MISMATCH")
A13: Expected (arithmetic annualized) return % | B13: mean * m | C13: =AVERAGE($B$6:$B$8)*Returns!$G$10*100 | D13: -0.64 | E13: =ROUND(C13,2)-D13 | F13: =IF(ABS(E13)<0.005,"OK","MISMATCH")
A14: Annualized volatility % | B14: annualized_volatility | C14: =STDEV($B$6:$B$8)*SQRT(Returns!$G$10)*100 | D14: 4.33 | E14: =ROUND(C14,2)-D14 | F14: =IF(ABS(E14)<0.005,"OK","MISMATCH")
A15: Max drawdown % | B15: max_drawdown | C15: =MIN($G$5:$G$8)*100 | D15: -1.36 | E15: =ROUND(C15,2)-D15 | F15: =IF(ABS(E15)<0.005,"OK","MISMATCH")
A16: Downside deviation % (sigma_down) | B16: sortino_ratio (MAR=0) | C16: =SQRT(SUMSQ($H$6:$H$8)/3)*SQRT(Returns!$G$10)*100
A17: Sharpe ex-post | B17: (R_ann - R_f)/sigma_ann | C17: =(C12-Returns!$G$11)/C14 | D17: -0.51 | E17: =ROUND(C17,2)-D17 | F17: =IF(ABS(E17)<0.005,"OK","MISMATCH")
A18: Sharpe ex-ante | B18: (mean_ann - R_f)/sigma_ann | C18: =(C13-Returns!$G$11)/C14 | D18: -0.49 | E18: =ROUND(C18,2)-D18 | F18: =IF(ABS(E18)<0.005,"OK","MISMATCH")
A19: Sortino | B19: (R_ann - R_f)/sigma_down | C19: =(C12-Returns!$G$11)/C16 | D19: -0.85 | E19: =ROUND(C19,2)-D19 | F19: =IF(ABS(E19)<0.005,"OK","MISMATCH")
A20: bestYearPct | B20: n/a | C20: not computable | D20: null | E20: correctly null - undefined for this short a window (3 monthly observations, < 1 calendar year) | F20: OK
A21: worstYearPct | B21: n/a | C21: not computable | D21: null | E21: correctly null - undefined for this short a window (3 monthly observations, < 1 calendar year) | F21: OK

Sheet Rolling
A1: ROLLING TAB VERIFICATION
A3: fold | B3: status | C3: explanation
A4: (none) | B4: 0 folds returned - EXPECTED, not a defect | C4: result.json's `rolling` array is empty. The request spans 2024-02-29 to 2024-05-31 (3 monthly return observations) while constraints.lookbackPeriodMonths = 12 with rollingWindowMode = 'expanding'. A 12-month lookback cannot be satisfied even once inside a ~4-month window, so no fold can be formed, let alone the 2 folds the engine requires. The backend says the same thing in result.robustNote: Rolling validation unavailable: not enough history for at least 2 folds at the selected frequency.
A6: Nothing to recompute here: there is no fold data to check against. The verification performed on this sheet is that the empty array is the arithmetically correct outcome of the request's own parameters.

Sheet Report
A1: REPORT TAB — CROSS-SHEET INTERNAL CONSISTENCY
A2: Not a new computation: each row asserts that a top-level scalar in result.json agrees with what the live formulas on the earlier sheets produce, or with the request that generated it.
A4: field | B4: given (result.json) | C4: cross-reference | D4: check
A5: feasibility | B5: ok | C5: weights sum to 1 and all weights within [minWeightPct, maxWeightPct] = [0, 100] | D5: =IF(AND(ABS(Weights!C7-1)<0.000001,Weights!C5>=0,Weights!C5<=1,Weights!C6>=0,Weights!C6<=1),"OK","MISMATCH")
A6: selectedRiskMeasure.measure | B6: std_dev | C6: request.riskMeasure = std_dev | D6: =IF(B6="std_dev","OK","MISMATCH")
A7: selectedRiskMeasure.optimizedValue | B7: 4.33 | C7: =Weights!C22 | D7: =IF(ABS(ROUND(C7,2)-B7)<0.005,"OK","MISMATCH")
A8: optimalPoint.volatilityPct | B8: 4.33 | C8: =Weights!C22 | D8: =IF(ABS(ROUND(C8,2)-B8)<0.005,"OK","MISMATCH")
A9: optimalPoint.expectedReturnPct | B9: -0.64 | C9: =Weights!C11 | D9: =IF(ABS(ROUND(C9,2)-B9)<0.005,"OK","MISMATCH")
A10: gmvPoint.volatilityPct | B10: 4.21 | C10: =Frontier!D5 | D10: =IF(ABS(ROUND(C10,2)-B10)<0.005,"OK","MISMATCH")
A11: tangencyPoint.volatilityPct | B11: 4.21 | C11: =Frontier!D5 | D11: =IF(ABS(ROUND(C11,2)-B11)<0.005,"OK","MISMATCH")
A12: totalTurnoverPct | B12: 50 | C12: =0.5*(ABS(Weights!C5)+ABS(Weights!C6))*100 | D12: =IF(ABS(0.5*(ABS(Weights!C5)+ABS(Weights!C6))*100-B12)<0.005,"OK","MISMATCH") | E12: turnover = 0.5 * sum|w_target - w_current|; request.currentWeightPct is {} so every current weight is 0, giving 0.5 * 100% = 50%
A13: generatedAt | B13: 2026-08-11T14:42:30Z | C13: run timestamp; nothing to recompute | D13: n/a
A14: robustNote | B14: Rolling validation unavailable: not enough history for at least 2 folds at the selected frequency. | C14: see Rolling sheet - 0 folds is arithmetically forced by lookbackPeriodMonths=12 over a 3-observation window | D14: OK
A15: feasibilityMessage | B15: null | C15: null expected: compareAgainst='none', groupConstraintsEnabled=false, robustOptimization=false | D15: OK
A16: compareNote | B16: null | C16: null expected: compareAgainst='none', groupConstraintsEnabled=false, robustOptimization=false | D16: OK
A17: constraintNote | B17: null | C17: null expected: compareAgainst='none', groupConstraintsEnabled=false, robustOptimization=false | D17: OK
A18: robustOptimizationNote | B18: null | C18: null expected: compareAgainst='none', groupConstraintsEnabled=false, robustOptimization=false | D18: OK

Sheet FullSolveReplication
A1: FULL SOLVE REPLICATION — closed-form 2-asset tangency portfolio
A2: This is the only sheet that re-derives the WEIGHTS themselves rather than the reporting layer. Inputs: mu and Sigma from the Weights sheet (which are live from NAV). result.json is used only in the yellow comparison column.
A4: quantity | B4: M0209_2548 | C4: M0155_2547
A5: mean monthly return mu (live) | B5: =Weights!D5 | C5: =Weights!D6
A6: monthly risk-free r_f = riskFreeRatePct/100/12 | B6: =Returns!$G$11/100/Returns!$G$10
A7: excess return mu - r_f | B7: =B5-$B$6 | C7: =C5-$B$6
A9: Sigma (monthly, from Weights sheet)
A10: s11 | B10: =Weights!$B$15
A11: s12 | B11: =Weights!$C$15
A12: s22 | B12: =Weights!$C$16
A13: det(Sigma) = s11*s22 - s12^2 | B13: =$B$10*$B$12-$B$11^2
A15: Unnormalized tangency weights u = Sigma^-1 * (mu - r_f), closed-form 2x2 inverse
A16: u1 = ( s22*e1 - s12*e2) / det | B16: =($B$12*B7-$B$11*C7)/$B$13
A17: u2 = (-s12*e1 + s11*e2) / det | B17: =(-$B$11*B7+$B$10*C7)/$B$13
A18: sum(u) | B18: =$B$16+$B$17
A20: Cross-check with Excel array functions (spills in Excel 365 / CSE in legacy Excel)
A21: MMULT(MINVERSE(Sigma), excess) [array formula in B] | B21: =MMULT(MINVERSE(Weights!$B$15:$C$16),TRANSPOSE(B7:C7)) | D21: should equal u1 (and u2 in the cell below when it spills)
A24: projId | B24: closed-form normalized weight (live) | C24: given optimalWeights (result.json) | D24: diff | E24: match to 6 dp?
A25: M0209_2548 | B25: =$B$16/$B$18 | C25: 0.97491886 | D25: =B25-C25 | E25: =IF(ABS(D25)<0.000001,"MATCH","DIFFERS")
A26: M0155_2547 | B26: =$B$17/$B$18 | C26: 0.02508114 | D26: =B26-C26 | E26: =IF(ABS(D26)<0.000001,"MATCH","DIFFERS")
A28: EXPECTED RESULT: DIFFERS. The closed-form tangency solution is UNCONSTRAINED and produces a short position, which the request forbids (constraints.longOnly = true, minWeightPct = 0). The grid below is the long-only comparison and is the meaningful check.
A31: Long-only Sharpe grid — the constrained solve, brute-forced live in Excel
A32: w(M0209_2548) | B32: w(M0155_2547) | C32: annualized return % | D32: annualized volatility % | E32: Sharpe (annualized, excess over 1.5%)
A33: 0 | B33: =1-A33 | C33: =(A33*Weights!$D$5+B33*Weights!$D$6)*Returns!$G$10*100 | D33: =SQRT(A33^2*Weights!$B$15+B33^2*Weights!$C$16+2*A33*B33*Weights!$C$15)*SQRT(Returns!$G$10)*100 | E33: =(C33-Returns!$G$11)/D33
A34: 0.05 | B34: =1-A34 | C34: =(A34*Weights!$D$5+B34*Weights!$D$6)*Returns!$G$10*100 | D34: =SQRT(A34^2*Weights!$B$15+B34^2*Weights!$C$16+2*A34*B34*Weights!$C$15)*SQRT(Returns!$G$10)*100 | E34: =(C34-Returns!$G$11)/D34
A35: 0.1 | B35: =1-A35 | C35: =(A35*Weights!$D$5+B35*Weights!$D$6)*Returns!$G$10*100 | D35: =SQRT(A35^2*Weights!$B$15+B35^2*Weights!$C$16+2*A35*B35*Weights!$C$15)*SQRT(Returns!$G$10)*100 | E35: =(C35-Returns!$G$11)/D35
A36: 0.15 | B36: =1-A36 | C36: =(A36*Weights!$D$5+B36*Weights!$D$6)*Returns!$G$10*100 | D36: =SQRT(A36^2*Weights!$B$15+B36^2*Weights!$C$16+2*A36*B36*Weights!$C$15)*SQRT(Returns!$G$10)*100 | E36: =(C36-Returns!$G$11)/D36
A37: 0.2 | B37: =1-A37 | C37: =(A37*Weights!$D$5+B37*Weights!$D$6)*Returns!$G$10*100 | D37: =SQRT(A37^2*Weights!$B$15+B37^2*Weights!$C$16+2*A37*B37*Weights!$C$15)*SQRT(Returns!$G$10)*100 | E37: =(C37-Returns!$G$11)/D37
A38: 0.25 | B38: =1-A38 | C38: =(A38*Weights!$D$5+B38*Weights!$D$6)*Returns!$G$10*100 | D38: =SQRT(A38^2*Weights!$B$15+B38^2*Weights!$C$16+2*A38*B38*Weights!$C$15)*SQRT(Returns!$G$10)*100 | E38: =(C38-Returns!$G$11)/D38
A39: 0.3 | B39: =1-A39 | C39: =(A39*Weights!$D$5+B39*Weights!$D$6)*Returns!$G$10*100 | D39: =SQRT(A39^2*Weights!$B$15+B39^2*Weights!$C$16+2*A39*B39*Weights!$C$15)*SQRT(Returns!$G$10)*100 | E39: =(C39-Returns!$G$11)/D39
A40: 0.35 | B40: =1-A40 | C40: =(A40*Weights!$D$5+B40*Weights!$D$6)*Returns!$G$10*100 | D40: =SQRT(A40^2*Weights!$B$15+B40^2*Weights!$C$16+2*A40*B40*Weights!$C$15)*SQRT(Returns!$G$10)*100 | E40: =(C40-Returns!$G$11)/D40
A41: 0.4 | B41: =1-A41 | C41: =(A41*Weights!$D$5+B41*Weights!$D$6)*Returns!$G$10*100 | D41: =SQRT(A41^2*Weights!$B$15+B41^2*Weights!$C$16+2*A41*B41*Weights!$C$15)*SQRT(Returns!$G$10)*100 | E41: =(C41-Returns!$G$11)/D41
A42: 0.45 | B42: =1-A42 | C42: =(A42*Weights!$D$5+B42*Weights!$D$6)*Returns!$G$10*100 | D42: =SQRT(A42^2*Weights!$B$15+B42^2*Weights!$C$16+2*A42*B42*Weights!$C$15)*SQRT(Returns!$G$10)*100 | E42: =(C42-Returns!$G$11)/D42
A43: 0.5 | B43: =1-A43 | C43: =(A43*Weights!$D$5+B43*Weights!$D$6)*Returns!$G$10*100 | D43: =SQRT(A43^2*Weights!$B$15+B43^2*Weights!$C$16+2*A43*B43*Weights!$C$15)*SQRT(Returns!$G$10)*100 | E43: =(C43-Returns!$G$11)/D43
A44: 0.55 | B44: =1-A44 | C44: =(A44*Weights!$D$5+B44*Weights!$D$6)*Returns!$G$10*100 | D44: =SQRT(A44^2*Weights!$B$15+B44^2*Weights!$C$16+2*A44*B44*Weights!$C$15)*SQRT(Returns!$G$10)*100 | E44: =(C44-Returns!$G$11)/D44
... A53: 1 | B53: =1-A53 | C53: =(A53*Weights!$D$5+B53*Weights!$D$6)*Returns!$G$10*100 | D53: =SQRT(A53^2*Weights!$B$15+B53^2*Weights!$C$16+2*A53*B53*Weights!$C$15)*SQRT(Returns!$G$10)*100 | E53: =(C53-Returns!$G$11)/D53
A54: =Weights!C5 | B54: =Weights!C6 | C54: =(A54*Weights!$D$5+B54*Weights!$D$6)*Returns!$G$10*100 | D54: =SQRT(A54^2*Weights!$B$15+B54^2*Weights!$C$16+2*A54*B54*Weights!$C$15)*SQRT(Returns!$G$10)*100 | E54: =(C54-Returns!$G$11)/D54 | F54: <- result.json's optimalWeights scored on the identical Sharpe formula
A56: best Sharpe on the long-only grid | B56: =MAX(E33:E53)
A57: argmax w(M0209_2548) on the grid | B57: =INDEX(A33:A53,MATCH(B56,E33:E53,0))
A58: Sharpe of result.json's optimalWeights | B58: =E54
...
